Workbook
Name NativeTimeline_Date: #N/A
Name NativeTimeline_Date1: #N/A
Name NativeTimeline_Date2: #N/A
Name NativeTimeline_Date3: #N/A
Name Slicer_Deficit: #N/A
Name Slicer_Height: #N/A
Name Slicer_Height1: #N/A
Name Slicer_Opponent: #N/A

Sheet Scores
A1: Angle | B1: Height | C1: Base | D1: Board | E1: Date | F1: Game | G1: Round | H1: Order | I1: Caleb | J1: Joshua | K1: Quadri | L1: Daniel | M1: Qianzi | N1: Kenny | O1: Veronica | P1: Joseph | Q1: Theo
A2: vertical | B2: mid | C2: no magnet | D2: Original | E2: 45707 | F2: 1 | G2: 1 | H2: CJQ | I2: 4 | J2: 0 | K2: 0
A3: vertical | B3: mid | C3: no magnet | D3: Original | E3: 45707 | F3: 1 | G3: 2 | H3: CJQ | I3: 3 | J3: 0 | K3: 0
A4: vertical | B4: mid | C4: no magnet | D4: Original | E4: 45707 | F4: 1 | G4: 3 | H4: CJQ | I4: 4 | J4: 1 | K4: 1
A5: vertical | B5: mid | C5: no magnet | D5: Original | E5: 45707 | F5: =F2+1 -> 2 | G5: =G2 -> 1 | H5: JC | I5: 8 | J5: 0
A6: vertical | B6: mid | C6: no magnet | D6: Original | E6: 45707 | F6: =F3+1 -> 2 | G6: =G3 -> 2 | H6: JC | I6: 5 | J6: 0
A7: vertical | B7: mid | C7: no magnet | D7: Original | E7: 45707 | F7: =F4+1 -> 2 | G7: =G4 -> 3 | H7: JC | I7: 3 | J7: 0
A8: vertical | B8: mid | C8: no magnet | D8: Original | E8: 45708 | F8: =F5+1 -> 3 | G8: =G5 -> 1 | H8: JC | I8: 1 | J8: 0
A9: vertical | B9: mid | C9: no magnet | D9: Original | E9: 45708 | F9: =F6+1 -> 3 | G9: =G6 -> 2 | H9: JC | I9: 6 | J9: 0
A10: vertical | B10: mid | C10: no magnet | D10: Original | E10: 45708 | F10: =F7+1 -> 3 | G10: =G7 -> 3 | H10: JC | I10: 3 | J10: 4
A11: vertical | B11: mid | C11: no magnet | D11: Original | E11: 45708 | F11: =F8+1 -> 4 | G11: =G8 -> 1 | H11: CJQ | I11: 3 | J11: 0 | K11: 1
A12: vertical | B12: mid | C12: no magnet | D12: Original | E12: 45708 | F12: =F9+1 -> 4 | G12: =G9 -> 2 | H12: CJQ | I12: 0 | J12: 0 | K12: 2
A13: vertical | B13: mid | C13: no magnet | D13: Original | E13: 45708 | F13: =F10+1 -> 4 | G13: =G10 -> 3 | H13: CJQ | I13: 1 | J13: 0 | K13: 4
A14: vertical | B14: mid | C14: no magnet | D14: Original | E14: 45708 | F14: =F11+1 -> 5 | G14: =G11 -> 1 | H14: QJC | I14: 5 | J14: 1 | K14: 1
A15: vertical | B15: mid | C15: no magnet | D15: Original | E15: 45708 | F15: =F12+1 -> 5 | G15: =G12 -> 2 | H15: QJC | I15: 4 | J15: 0 | K15: 2
A16: vertical | B16: mid | C16: no magnet | D16: Original | E16: 45708 | F16: =F13+1 -> 5 | G16: =G13 -> 3 | H16: QJC | I16: 2 | J16: 0 | K16: 0
A17: vertical | B17: mid | C17: no magnet | D17: Original | E17: 45709 | F17: =F14+1 -> 6 | G17: =G14 -> 1 | H17: JC | I17: 7 | J17: 0
A18: vertical | B18: mid | C18: no magnet | D18: Original | E18: 45709 | F18: =F15+1 -> 6 | G18: =G15 -> 2 | H18: JC | I18: 2 | J18: 4
A19: vertical | B19: mid | C19: no magnet | D19: Original | E19: 45709 | F19: =F16+1 -> 6 | G19: =G16 -> 3 | H19: JC | I19: 1 | J19: 0
A20: vertical | B20: mid | C20: no magnet | D20: Original | E20: 45712 | F20: =F17+1 -> 7 | G20: =G17 -> 1 | H20: CJ | I20: 0 | J20: 1
A21: vertical | B21: mid | C21: no magnet | D21: Original | E21: 45712 | F21: =F18+1 -> 7 | G21: =G18 -> 2 | H21: CJ | I21: 5 | J21: 2
A22: vertical | B22: mid | C22: no magnet | D22: Original | E22: 45712 | F22: =F19+1 -> 7 | G22: =G19 -> 3 | H22: CJ | I22: 0 | J22: 6
A23: vertical | B23: mid | C23: no magnet | D23: Original | E23: 45712 | F23: =F20+1 -> 8 | G23: =G20 -> 1 | H23: CJ | I23: 0 | J23: 1
A24: vertical | B24: mid | C24: no magnet | D24: Original | E24: 45712 | F24: =F21+1 -> 8 | G24: =G21 -> 2 | H24: CJ | I24: 3 | J24: 1
A25: vertical | B25: mid | C25: no magnet | D25: Original | E25: 45712 | F25: =F22+1 -> 8 | G25: =G22 -> 3 | H25: CJ | I25: 3 | J25: 0
A26: vertical | B26: mid | C26: no magnet | D26: Original | E26: 45713 | F26: =F23+1 -> 9 | G26: =G23 -> 1 | H26: CJQ | I26: 2 | J26: 1 | K26: 0
A27: vertical | B27: mid | C27: no magnet | D27: Original | E27: 45713 | F27: =F24+1 -> 9 | G27: =G24 -> 2 | H27: CJQ | I27: 5 | J27: 3 | K27: 1
A28: vertical | B28: mid | C28: no magnet | D28: Original | E28: 45713 | F28: =F25+1 -> 9 | G28: =G25 -> 3 | H28: CJQ | I28: 2 | J28: 7 | K28: 3
A29: vertical | B29: mid | C29: no magnet | D29: Original | E29: 45713 | F29: =F26+1 -> 10 | G29: =G26 -> 1 | H29: CJ | I29: 0 | J29: 1
A30: vertical | B30: mid | C30: no magnet | D30: Original | E30: 45713 | F30: =F27+1 -> 10 | G30: =G27 -> 2 | H30: CJ | I30: 3 | J30: 0
A31: vertical | B31: mid | C31: no magnet | D31: Original | E31: 45713 | F31: =F28+1 -> 10 | G31: =G28 -> 3 | H31: CJ | I31: 3 | J31: 0
A32: vertical | B32: mid | C32: magnet | D32: Original | E32: 45714 | F32: =F29+1 -> 11 | G32: =G29 -> 1 | H32: DCJ | I32: 5 | J32: 0 | L32: 1
A33: vertical | B33: mid | C33: magnet | D33: Original | E33: 45714 | F33: =F30+1 -> 11 | G33: =G30 -> 2 | H33: DCJ | I33: 6 | J33: 2 | L33: 3
A34: vertical | B34: mid | C34: magnet | D34: Original | E34: 45714 | F34: =F31+1 -> 11 | G34: =G31 -> 3 | H34: DCJ | I34: 3 | J34: 3 | L34: 2
A35: vertical | B35: mid | C35: magnet | D35: Original | E35: 45715 | F35: =F32+1 -> 12 | G35: =G32 -> 1 | H35: CJD | I35: 1 | J35: 0 | L35: 2
A36: vertical | B36: mid | C36: magnet | D36: Original | E36: 45715 | F36: =F33+1 -> 12 | G36: =G33 -> 2 | H36: CJD | I36: 6 | J36: 1 | L36: 0
A37: vertical | B37: mid | C37: magnet | D37: Original | E37: 45715 | F37: =F34+1 -> 12 | G37: =G34 -> 3 | H37: CJD | I37: 3 | J37: 2 | L37: 1
A38: vertical | B38: mid | C38: magnet | D38: Original | E38: 45715 | F38: =F35+1 -> 13 | G38: =G35 -> 1 | H38: DCJ | I38: 3 | J38: 0 | L38: 0
A39: vertical | B39: mid | C39: magnet | D39: Original | E39: 45715 | F39: =F36+1 -> 13 | G39: =G36 -> 2 | H39: DCJ | I39: 5 | J39: 1 | L39: 0
A40: vertical | B40: mid | C40: magnet | D40: Original | E40: 45715 | F40: =F37+1 -> 13 | G40: =G37 -> 3 | H40: DCJ | I40: 3 | J40: 0 | L40: 0
...

Sheet Games
A1: Angle | B1: Height | C1: Base | D1: Date | E1: Game | F1: Order | G1: Rounds | H1: Player | I1: Total Score | J1: Victory | K1: DD | L1: Cons DD
A2: vertical | B2: 256 | C2: tape-magnet | D2: 46063 | E2: 262 | F2: JC | G2: 3 | H2: Caleb | I2: 21 | J2: 1 | K2: =IF(Convert_to_Games[[#This Row],[Total Score]]>9, 1, 0) -> 1 | L2: =IF(Convert_to_Games[[#This Row],[DD]]=0, 0, IF(L1 = "Cons DD", Convert_to_Games[[#This Row],[DD]], L1+L1)) -> 1
A3: vertical | B3: 256 | C3: tape-magnet | D3: 46078 | E3: 266 | F3: CJ | G3: 3 | H3: Caleb | I3: 21 | J3: 1 | K3: =IF(Convert_to_Games[[#This Row],[Total Score]]>9, 1, 0) -> 1 | L3: =IF(Convert_to_Games[[#This Row],[DD]]=0, 0, IF(L2 = "Cons DD", Convert_to_Games[[#This Row],[DD]], L2+L2)) -> 2
A4: vertical | B4: 256 | C4: tape-magnet | D4: 46122 | E4: 281 | F4: JC | G4: 4 | H4: Caleb | I4: 21 | J4: 1 | K4: =IF(Convert_to_Games[[#This Row],[Total Score]]>9, 1, 0) -> 1 | L4: =IF(Convert_to_Games[[#This Row],[DD]]=0, 0, IF(L3 = "Cons DD", Convert_to_Games[[#This Row],[DD]], L3+L3)) -> 4
A5: vertical | B5: 256 | C5: tape-magnet | D5: 46058 | E5: 260 | F5: JC | G5: 4 | H5: Caleb | I5: 20 | J5: 1 | K5: =IF(Convert_to_Games[[#This Row],[Total Score]]>9, 1, 0) -> 1 | L5: =IF(Convert_to_Games[[#This Row],[DD]]=0, 0, IF(L4 = "Cons DD", Convert_to_Games[[#This Row],[DD]], L4+L4)) -> 8
A6: vertical | B6: 256 | C6: tape-magnet | D6: 46073 | E6: 264 | F6: CJ | G6: 3 | H6: Caleb | I6: 20 | J6: 1 | K6: =IF(Convert_to_Games[[#This Row],[Total Score]]>9, 1, 0) -> 1 | L6: =IF(Convert_to_Games[[#This Row],[DD]]=0, 0, IF(L5 = "Cons DD", Convert_to_Games[[#This Row],[DD]], L5+L5)) -> 16
A7: vertical | B7: 256 | C7: tape-magnet | D7: 46127 | E7: 282 | F7: CJ | G7: 4 | H7: Caleb | I7: 20 | J7: 1 | K7: =IF(Convert_to_Games[[#This Row],[Total Score]]>9, 1, 0) -> 1 | L7: =IF(Convert_to_Games[[#This Row],[DD]]=0, 0, IF(L6 = "Cons DD", Convert_to_Games[[#This Row],[DD]], L6+L6)) -> 32
A8: vertical | B8: 256 | C8: tape-magnet | D8: 46132 | E8: 283 | F8: CJ | G8: 4 | H8: Caleb | I8: 20 | J8: 1 | K8: =IF(Convert_to_Games[[#This Row],[Total Score]]>9, 1, 0) -> 1 | L8: =IF(Convert_to_Games[[#This Row],[DD]]=0, 0, IF(L7 = "Cons DD", Convert_to_Games[[#This Row],[DD]], L7+L7)) -> 64
A9: vertical | B9: 256 | C9: tape-magnet | D9: 45881 | E9: 202 | F9: CJD | G9: 3 | H9: Caleb | I9: 19 | J9: 1 | K9: =IF(Convert_to_Games[[#This Row],[Total Score]]>9, 1, 0) -> 1 | L9: =IF(Convert_to_Games[[#This Row],[DD]]=0, 0, IF(L8 = "Cons DD", Convert_to_Games[[#This Row],[DD]], L8+L8)) -> 128
A10: vertical | B10: 256 | C10: tape-magnet | D10: 45961 | E10: 238 | F10: JC | G10: 3 | H10: Caleb | I10: 19 | J10: 1 | K10: =IF(Convert_to_Games[[#This Row],[Total Score]]>9, 1, 0) -> 1 | L10: =IF(Convert_to_Games[[#This Row],[DD]]=0, 0, IF(L9 = "Cons DD", Convert_to_Games[[#This Row],[DD]], L9+L9)) -> 256
A11: vertical | B11: 256 | C11: tape-magnet | D11: 45979 | E11: 241 | F11: JTCV | G11: 3 | H11: Caleb | I11: 19 | J11: 1 | K11: =IF(Convert_to_Games[[#This Row],[Total Score]]>9, 1, 0) -> 1 | L11: =IF(Convert_to_Games[[#This Row],[DD]]=0, 0, IF(L10 = "Cons DD", Convert_to_Games[[#This Row],[DD]], L10+L10)) -> 512
A12: vertical | B12: 256 | C12: tape-magnet | D12: 46034 | E12: 253 | F12: JC | G12: 3 | H12: Caleb | I12: 19 | J12: 1 | K12: =IF(Convert_to_Games[[#This Row],[Total Score]]>9, 1, 0) -> 1 | L12: =IF(Convert_to_Games[[#This Row],[DD]]=0, 0, IF(L11 = "Cons DD", Convert_to_Games[[#This Row],[DD]], L11+L11)) -> 1024
A13: vertical | B13: 256 | C13: tape-magnet | D13: 46044 | E13: 256 | F13: JC | G13: 4 | H13: Joshua | I13: 19 | J13: 1 | K13: =IF(Convert_to_Games[[#This Row],[Total Score]]>9, 1, 0) -> 1 | L13: =IF(Convert_to_Games[[#This Row],[DD]]=0, 0, IF(L12 = "Cons DD", Convert_to_Games[[#This Row],[DD]], L12+L12)) -> 2048
... A15: vertical | B15: 256 | C15: tape-magnet | D15: 46198 | E15: 288 | F15: CJ | G15: 4 | H15: Caleb | I15: 19 | J15: 1 | K15: =IF(Convert_to_Games[[#This Row],[Total Score]]>9, 1, 0) -> 1 | L15: =IF(Convert_to_Games[[#This Row],[DD]]=0, 0, IF(L14 = "Cons DD", Convert_to_Games[[#This Row],[DD]], L14+L14)) -> 8192
A16: vertical | B16: mid | C16: tape-magnet | D16: 45875 | E16: 197 | F16: CJ | G16: 3 | H16: Caleb | I16: 18 | J16: 1 | K16: =IF(Convert_to_Games[[#This Row],[Total Score]]>9, 1, 0) -> 1 | L16: =IF(Convert_to_Games[[#This Row],[DD]]=0, 0, IF(L15 = "Cons DD", Convert_to_Games[[#This Row],[DD]], L15+L15)) -> 16384
A17: vertical | B17: 256 | C17: tape-magnet | D17: 45881 | E17: 203 | F17: JCV | G17: 3 | H17: Caleb | I17: 18 | J17: 1 | K17: =IF(Convert_to_Games[[#This Row],[Total Score]]>9, 1, 0) -> 1 | L17: =IF(Convert_to_Games[[#This Row],[DD]]=0, 0, IF(L16 = "Cons DD", Convert_to_Games[[#This Row],[DD]], L16+L16)) -> 32768
A18: vertical | B18: 256 | C18: tape-magnet | D18: 45882 | E18: 204 | F18: CJ | G18: 4 | H18: Caleb | I18: 18 | J18: 1 | K18: =IF(Convert_to_Games[[#This Row],[Total Score]]>9, 1, 0) -> 1 | L18: =IF(Convert_to_Games[[#This Row],[DD]]=0, 0, IF(L17 = "Cons DD", Convert_to_Games[[#This Row],[DD]], L17+L17)) -> 65536
A19: vertical | B19: 256 | C19: tape-magnet | D19: 45959 | E19: 237 | F19: CJ | G19: 3 | H19: Joshua | I19: 18 | J19: 1 | K19: =IF(Convert_to_Games[[#This Row],[Total Score]]>9, 1, 0) -> 1 | L19: =IF(Convert_to_Games[[#This Row],[DD]]=0, 0, IF(L18 = "Cons DD", Convert_to_Games[[#This Row],[DD]], L18+L18)) -> 131072
A20: vertical | B20: 256 | C20: tape-magnet | D20: 45992 | E20: 244 | F20: CJ | G20: 5 | H20: Joshua | I20: 18 | J20: 1 | K20: =IF(Convert_to_Games[[#This Row],[Total Score]]>9, 1, 0) -> 1 | L20: =IF(Convert_to_Games[[#This Row],[DD]]=0, 0, IF(L19 = "Cons DD", Convert_to_Games[[#This Row],[DD]], L19+L19)) -> 262144
A21: vertical | B21: 256 | C21: tape-magnet | D21: 46036 | E21: 255 | F21: CJ | G21: 3 | H21: Caleb | I21: 18 | J21: 1 | K21: =IF(Convert_to_Games[[#This Row],[Total Score]]>9, 1, 0) -> 1 | L21: =IF(Convert_to_Games[[#This Row],[DD]]=0, 0, IF(L20 = "Cons DD", Convert_to_Games[[#This Row],[DD]], L20+L20)) -> 524288
A22: vertical | B22: 256 | C22: tape-magnet | D22: 46059 | E22: 261 | F22: JC | G22: 3 | H22: Caleb | I22: 18 | J22: 1 | K22: =IF(Convert_to_Games[[#This Row],[Total Score]]>9, 1, 0) -> 1 | L22: =IF(Convert_to_Games[[#This Row],[DD]]=0, 0, IF(L21 = "Cons DD", Convert_to_Games[[#This Row],[DD]], L21+L21)) -> 1048576
A23: vertical | B23: 256 | C23: tape-magnet | D23: 46091 | E23: 272 | F23: JC | G23: 3 | H23: Caleb | I23: 18 | J23: 1 | K23: =IF(Convert_to_Games[[#This Row],[Total Score]]>9, 1, 0) -> 1 | L23: =IF(Convert_to_Games[[#This Row],[DD]]=0, 0, IF(L22 = "Cons DD", Convert_to_Games[[#This Row],[DD]], L22+L22)) -> 2097152
A24: vertical | B24: 256 | C24: tape-magnet | D24: 46093 | E24: 274 | F24: JC | G24: 4 | H24: Caleb | I24: 18 | J24: 1 | K24: =IF(Convert_to_Games[[#This Row],[Total Score]]>9, 1, 0) -> 1 | L24: =IF(Convert_to_Games[[#This Row],[DD]]=0, 0, IF(L23 = "Cons DD", Convert_to_Games[[#This Row],[DD]], L23+L23)) -> 4194304
A25: vertical | B25: 256 | C25: tape-magnet | D25: 46114 | E25: 279 | F25: JC | G25: 4 | H25: Caleb | I25: 18 | J25: 1 | K25: =IF(Convert_to_Games[[#This Row],[Total Score]]>9, 1, 0) -> 1 | L25: =IF(Convert_to_Games[[#This Row],[DD]]=0, 0, IF(L24 = "Cons DD", Convert_to_Games[[#This Row],[DD]], L24+L24)) -> 8388608
A26: vertical | B26: 256 | C26: tape-magnet | D26: 46121 | E26: 280 | F26: CJ | G26: 4 | H26: Caleb | I26: 18 | J26: 1 | K26: =IF(Convert_to_Games[[#This Row],[Total Score]]>9, 1, 0) -> 1 | L26: =IF(Convert_to_Games[[#This Row],[DD]]=0, 0, IF(L25 = "Cons DD", Convert_to_Games[[#This Row],[DD]], L25+L25)) -> 16777216
A27: vertical | B27: 256 | C27: tape-magnet | D27: 46156 | E27: 286 | F27: JC | G27: 4 | H27: Caleb | I27: 18 | J27: 1 | K27: =IF(Convert_to_Games[[#This Row],[Total Score]]>9, 1, 0) -> 1 | L27: =IF(Convert_to_Games[[#This Row],[DD]]=0, 0, IF(L26 = "Cons DD", Convert_to_Games[[#This Row],[DD]], L26+L26)) -> 33554432
A28: vertical | B28: mid | C28: magnet | D28: 45840 | E28: 144 | F28: CJQ | G28: 3 | H28: Caleb | I28: 17 | J28: 1 | K28: =IF(Convert_to_Games[[#This Row],[Total Score]]>9, 1, 0) -> 1 | L28: =IF(Convert_to_Games[[#This Row],[DD]]=0, 0, IF(L27 = "Cons DD", Convert_to_Games[[#This Row],[DD]], L27+L27)) -> 67108864
A29: vertical | B29: mid | C29: magnet | D29: 45846 | E29: 151 | F29: BC | G29: 3 | H29: Caleb | I29: 17 | J29: 1 | K29: =IF(Convert_to_Games[[#This Row],[Total Score]]>9, 1, 0) -> 1 | L29: =IF(Convert_to_Games[[#This Row],[DD]]=0, 0, IF(L28 = "Cons DD", Convert_to_Games[[#This Row],[DD]], L28+L28)) -> 134217728
A30: vertical | B30: 256 | C30: tape-magnet | D30: 45896 | E30: 211 | F30: CJV | G30: 3 | H30: Caleb | I30: 17 | J30: 1 | K30: =IF(Convert_to_Games[[#This Row],[Total Score]]>9, 1, 0) -> 1 | L30: =IF(Convert_to_Games[[#This Row],[DD]]=0, 0, IF(L29 = "Cons DD", Convert_to_Games[[#This Row],[DD]], L29+L29)) -> 268435456
A31: vertical | B31: 256 | C31: tape-magnet | D31: 45904 | E31: 216 | F31: CJ | G31: 3 | H31: Caleb | I31: 17 | J31: 1 | K31: =IF(Convert_to_Games[[#This Row],[Total Score]]>9, 1, 0) -> 1 | L31: =IF(Convert_to_Games[[#This Row],[DD]]=0, 0, IF(L30 = "Cons DD", Convert_to_Games[[#This Row],[DD]], L30+L30)) -> 536870912
A32: vertical | B32: 256 | C32: tape-magnet | D32: 46080 | E32: 267 | F32: JC | G32: 3 | H32: Caleb | I32: 17 | J32: 1 | K32: =IF(Convert_to_Games[[#This Row],[Total Score]]>9, 1, 0) -> 1 | L32: =IF(Convert_to_Games[[#This Row],[DD]]=0, 0, IF(L31 = "Cons DD", Convert_to_Games[[#This Row],[DD]], L31+L31)) -> 1073741824
A33: vertical | B33: 256 | C33: tape-magnet | D33: 46092 | E33: 273 | F33: CJQ | G33: 4 | H33: Caleb | I33: 17 | J33: 1 | K33: =IF(Convert_to_Games[[#This Row],[Total Score]]>9, 1, 0) -> 1 | L33: =IF(Convert_to_Games[[#This Row],[DD]]=0, 0, IF(L32 = "Cons DD", Convert_to_Games[[#This Row],[DD]], L32+L32)) -> 2147483648
A34: vertical | B34: 256 | C34: tape-magnet | D34: 46106 | E34: 277 | F34: CJ | G34: 4 | H34: Caleb | I34: 17 | J34: 1 | K34: =IF(Convert_to_Games[[#This Row],[Total Score]]>9, 1, 0) -> 1 | L34: =IF(Convert_to_Games[[#This Row],[DD]]=0, 0, IF(L33 = "Cons DD", Convert_to_Games[[#This Row],[DD]], L33+L33)) -> 4294967296
A35: vertical | B35: 256 | C35: tape-magnet | D35: 46154 | E35: 285 | F35: CJ | G35: 4 | H35: Caleb | I35: 17 | J35: 1 | K35: =IF(Convert_to_Games[[#This Row],[Total Score]]>9, 1, 0) -> 1 | L35: =IF(Convert_to_Games[[#This Row],[DD]]=0, 0, IF(L34 = "Cons DD", Convert_to_Games[[#This Row],[DD]], L34+L34)) -> 8589934592
A36: vertical | B36: mid | C36: no magnet | D36: 45707 | E36: 2 | F36: JC | G36: 3 | H36: Caleb | I36: 16 | J36: 1 | K36: =IF(Convert_to_Games[[#This Row],[Total Score]]>9, 1, 0) -> 1 | L36: =IF(Convert_to_Games[[#This Row],[DD]]=0, 0, IF(L35 = "Cons DD", Convert_to_Games[[#This Row],[DD]], L35+L35)) -> 17179869184
A37: vertical | B37: mid | C37: magnet | D37: 45835 | E37: 135 | F37: CJ | G37: 3 | H37: Caleb | I37: 16 | J37: 1 | K37: =IF(Convert_to_Games[[#This Row],[Total Score]]>9, 1, 0) -> 1 | L37: =IF(Convert_to_Games[[#This Row],[DD]]=0, 0, IF(L36 = "Cons DD", Convert_to_Games[[#This Row],[DD]], L36+L36)) -> 34359738368
A38: vertical | B38: mid | C38: tape-magnet | D38: 45869 | E38: 189 | F38: JC | G38: 3 | H38: Caleb | I38: 16 | J38: 1 | K38: =IF(Convert_to_Games[[#This Row],[Total Score]]>9, 1, 0) -> 1 | L38: =IF(Convert_to_Games[[#This Row],[DD]]=0, 0, IF(L37 = "Cons DD", Convert_to_Games[[#This Row],[DD]], L37+L37)) -> 68719476736
A39: vertical | B39: mid | C39: tape-magnet | D39: 45875 | E39: 198 | F39: JC | G39: 3 | H39: Joshua | I39: 16 | J39: 1 | K39: =IF(Convert_to_Games[[#This Row],[Total Score]]>9, 1, 0) -> 1 | L39: =IF(Convert_to_Games[[#This Row],[DD]]=0, 0, IF(L38 = "Cons DD", Convert_to_Games[[#This Row],[DD]], L38+L38)) -> 137438953472
A40: vertical | B40: 256 | C40: tape-magnet | D40: 45915 | E40: 219 | F40: JC | G40: 3 | H40: Caleb | I40: 16 | J40: 1 | K40: =IF(Convert_to_Games[[#This Row],[Total Score]]>9, 1, 0) -> 1 | L40: =IF(Convert_to_Games[[#This Row],[DD]]=0, 0, IF(L39 = "Cons DD", Convert_to_Games[[#This Row],[DD]], L39+L39)) -> 274877906944
A41: vertical | B41: 256 | C41: tape-magnet | D41: 45940 | E41: 231 | F41: CJ | G41: 3 | H41: Caleb | I41: 16 | J41: 1 | K41: =IF(Convert_to_Games[[#This Row],[Total Score]]>9, 1, 0) -> 1 | L41: =IF(Convert_to_Games[[#This Row],[DD]]=0, 0, IF(L40 = "Cons DD", Convert_to_Games[[#This Row],[DD]], L40+L40)) -> 549755813888
...

Sheet Records
A1: Angle | B1: Height | C1: Base | D1: Date | E1: Game | F1: Player | G1: Order | H1: Total Score | I1: Opponent | J1: Result | K1: Win | L1: Loss | M1: Tie | N1: Total Games | P1: Angle | Q1: (All)
A2: vertical | B2: mid | C2: no magnet | D2: 45707 | E2: 1 | F2: Caleb | G2: First | H2: 11 | I2: Joshua | J2: Win | K2: 1 | L2: 0 | M2: 0 | N2: 1 | P2: Height | Q2: (All)
A3: vertical | B3: mid | C3: no magnet | D3: 45707 | E3: 1 | F3: Caleb | G3: First | H3: 11 | I3: Quadri | J3: Win | K3: 1 | L3: 0 | M3: 0 | N3: 1 | P3: Base | Q3: (All)
A4: vertical | B4: mid | C4: no magnet | D4: 45707 | E4: 1 | F4: Joshua | G4: Last | H4: 1 | I4: Caleb | J4: Loss | K4: 0 | L4: 1 | M4: 0 | N4: 1 | P4: Order | Q4: (All)
A5: vertical | B5: mid | C5: no magnet | D5: 45707 | E5: 1 | F5: Joshua | G5: First | H5: 1 | I5: Quadri | J5: Tie | K5: 0 | L5: 0 | M5: 1 | N5: 1
A6: vertical | B6: mid | C6: no magnet | D6: 45707 | E6: 1 | F6: Quadri | G6: Last | H6: 1 | I6: Caleb | J6: Loss | K6: 0 | L6: 1 | M6: 0 | N6: 1 | P6: Player | Q6: Matchups | R6: Wins | S6: Ties | T6: Losses | U6: Win Rate | V6: Average Score
A7: vertical | B7: mid | C7: no magnet | D7: 45707 | E7: 1 | F7: Quadri | G7: Last | H7: 1 | I7: Joshua | J7: Tie | K7: 0 | L7: 0 | M7: 1 | N7: 1 | P7: Caleb | Q7: 21 | R7: 20 | S7: 0 | T7: 1 | U7: 0.95238095 | V7: 15.714286
A8: vertical | B8: mid | C8: no magnet | D8: 45707 | E8: 2 | F8: Caleb | G8: Last | H8: 16 | I8: Joshua | J8: Win | K8: 1 | L8: 0 | M8: 0 | N8: 1 | P8: Daniel | Q8: 1 | R8: 0 | S8: 1 | T8: 0 | U8: 0.5 | V8: 9
A9: vertical | B9: mid | C9: no magnet | D9: 45707 | E9: 2 | F9: Joshua | G9: First | H9: 0 | I9: Caleb | J9: Loss | K9: 0 | L9: 1 | M9: 0 | N9: 1 | P9: Quadri | Q9: 2 | R9: 0 | S9: 1 | T9: 1 | U9: 0.25 | V9: 4.5
A10: vertical | B10: mid | C10: no magnet | D10: 45708 | E10: 3 | F10: Caleb | G10: Last | H10: 10 | I10: Joshua | J10: Win | K10: 1 | L10: 0 | M10: 0 | N10: 1 | P10: Veronica | Q10: 1 | R10: 0 | S10: 0 | T10: 1 | U10: 0 | V10: 6
A11: vertical | B11: mid | C11: no magnet | D11: 45708 | E11: 3 | F11: Joshua | G11: First | H11: 4 | I11: Caleb | J11: Loss | K11: 0 | L11: 1 | M11: 0 | N11: 1 | P11: Grand Total | Q11: 25 | R11: 20 | S11: 2 | T11: 3 | U11: 0.84 | V11: 14.16
A12: vertical | B12: mid | C12: no magnet | D12: 45708 | E12: 4 | F12: Caleb | G12: First | H12: 4 | I12: Joshua | J12: Win | K12: 1 | L12: 0 | M12: 0 | N12: 1
A13: vertical | B13: mid | C13: no magnet | D13: 45708 | E13: 4 | F13: Joshua | G13: Last | H13: 0 | I13: Caleb | J13: Loss | K13: 0 | L13: 1 | M13: 0 | N13: 1
A14: vertical | B14: mid | C14: no magnet | D14: 45708 | E14: 4 | F14: Joshua | G14: First | H14: 0 | I14: Quadri | J14: Loss | K14: 0 | L14: 1 | M14: 0 | N14: 1
A15: vertical | B15: mid | C15: no magnet | D15: 45708 | E15: 4 | F15: Quadri | G15: Last | H15: 7 | I15: Caleb | J15: Win | K15: 1 | L15: 0 | M15: 0 | N15: 1
A16: vertical | B16: mid | C16: no magnet | D16: 45708 | E16: 4 | F16: Quadri | G16: Last | H16: 7 | I16: Joshua | J16: Win | K16: 1 | L16: 0 | M16: 0 | N16: 1
A17: vertical | B17: mid | C17: no magnet | D17: 45708 | E17: 4 | F17: Caleb | G17: First | H17: 4 | I17: Quadri | J17: Loss | K17: 0 | L17: 1 | M17: 0 | N17: 1
A18: vertical | B18: mid | C18: no magnet | D18: 45708 | E18: 5 | F18: Quadri | G18: First | H18: 3 | I18: Joshua | J18: Win | K18: 1 | L18: 0 | M18: 0 | N18: 1
A19: vertical | B19: mid | C19: no magnet | D19: 45708 | E19: 5 | F19: Quadri | G19: First | H19: 3 | I19: Caleb | J19: Loss | K19: 0 | L19: 1 | M19: 0 | N19: 1
A20: vertical | B20: mid | C20: no magnet | D20: 45708 | E20: 5 | F20: Joshua | G20: Last | H20: 1 | I20: Quadri | J20: Loss | K20: 0 | L20: 1 | M20: 0 | N20: 1
A21: vertical | B21: mid | C21: no magnet | D21: 45708 | E21: 5 | F21: Joshua | G21: First | H21: 1 | I21: Caleb | J21: Loss | K21: 0 | L21: 1 | M21: 0 | N21: 1
A22: vertical | B22: mid | C22: no magnet | D22: 45708 | E22: 5 | F22: Caleb | G22: Last | H22: 11 | I22: Quadri | J22: Win | K22: 1 | L22: 0 | M22: 0 | N22: 1
A23: vertical | B23: mid | C23: no magnet | D23: 45708 | E23: 5 | F23: Caleb | G23: Last | H23: 11 | I23: Joshua | J23: Win | K23: 1 | L23: 0 | M23: 0 | N23: 1
... A675: vertical | B675: mid | C675: tape-magnet | D675: 45876 | E675: 200 | F675: Caleb | G675: Last | H675: 14 | I675: Joshua | J675: Win | K675: 1 | L675: 0 | M675: 0 | N675: 1
A676: vertical | B676: 256 | C676: tape-magnet | D676: 45880 | E676: 201 | F676: Caleb | G676: Last | H676: 9 | I676: Joshua | J676: Win | K676: 1 | L676: 0 | M676: 0 | N676: 1
A677: vertical | B677: 256 | C677: tape-magnet | D677: 45880 | E677: 201 | F677: Joshua | G677: First | H677: 6 | I677: Caleb | J677: Loss | K677: 0 | L677: 1 | M677: 0 | N677: 1
A678: vertical | B678: 256 | C678: tape-magnet | D678: 45881 | E678: 202 | F678: Joshua | G678: Last | H678: 12 | I678: Caleb | J678: Loss | K678: 0 | L678: 1 | M678: 0 | N678: 1
A679: vertical | B679: 256 | C679: tape-magnet | D679: 45881 | E679: 202 | F679: Daniel | G679: Last | H679: 4 | I679: Joshua | J679: Loss | K679: 0 | L679: 1 | M679: 0 | N679: 1
A680: vertical | B680: 256 | C680: tape-magnet | D680: 45881 | E680: 202 | F680: Joshua | G680: First | H680: 12 | I680: Daniel | J680: Win | K680: 1 | L680: 0 | M680: 0 | N680: 1
A681: vertical | B681: 256 | C681: tape-magnet | D681: 45881 | E681: 202 | F681: Caleb | G681: First | H681: 19 | I681: Daniel | J681: Win | K681: 1 | L681: 0 | M681: 0 | N681: 1
A682: vertical | B682: 256 | C682: tape-magnet | D682: 45881 | E682: 202 | F682: Caleb | G682: First | H682: 19 | I682: Joshua | J682: Win | K682: 1 | L682: 0 | M682: 0 | N682: 1
A683: vertical | B683: 256 | C683: tape-magnet | D683: 45881 | E683: 202 | F683: Daniel | G683: Last | H683: 4 | I683: Caleb | J683: Loss | K683: 0 | L683: 1 | M683: 0 | N683: 1
A684: vertical | B684: 256 | C684: tape-magnet | D684: 45881 | E684: 203 | F684: Caleb | G684: Last | H684: 18 | I684: Joshua | J684: Win | K684: 1 | L684: 0 | M684: 0 | N684: 1
A685: vertical | B685: 256 | C685: tape-magnet | D685: 45881 | E685: 203 | F685: Caleb | G685: First | H685: 18 | I685: Veronica | J685: Win | K685: 1 | L685: 0 | M685: 0 | N685: 1
A686: vertical | B686: 256 | C686: tape-magnet | D686: 45881 | E686: 203 | F686: Joshua | G686: First | H686: 13 | I686: Caleb | J686: Loss | K686: 0 | L686: 1 | M686: 0 | N686: 1
A687: vertical | B687: 256 | C687: tape-magnet | D687: 45881 | E687: 203 | F687: Joshua | G687: First | H687: 13 | I687: Veronica | J687: Win | K687: 1 | L687: 0 | M687: 0 | N687: 1
... A915: vertical | B915: 256 | C915: tape-magnet | D915: 46198 | E915: 288 | F915: Joshua | G915: Last | H915: 10 | I915: Caleb | J915: Loss | K915: 0 | L915: 1 | M915: 0 | N915: 1

Sheet Clutch
A1: Date | B1: Game | C1: First | D1: Player | E1: Round | F1: Deficit | G1: Success
A2: 45707 | B2: 1 | C2: Caleb | D2: Joshua | E2: 3 | F2: 11 | G2: 0 | K2: Round | L2: (All)
A3: 45707 | B3: 2 | C3: Joshua | D3: Joshua | E3: 3 | F3: 13 | G3: 0 | K3: First | L3: (All)
A4: 45708 | B4: 3 | C4: Joshua | D4: Joshua | E4: 3 | F4: 7 | G4: 0
A5: 45708 | B5: 4 | C5: Caleb | D5: Joshua | E5: 3 | F5: 4 | G5: 0 | K5: Row Labels | L5: Opportunities | M5: Success Rate
A6: 45708 | B6: 5 | C6: Joshua | D6: Joshua | E6: 3 | F6: 8 | G6: 0 | K6: Caleb | L6: 6 | M6: 0.33333333
A7: 45709 | B7: 6 | C7: Joshua | D7: Joshua | E7: 3 | F7: 5 | G7: 0 | K7: Joshua | L7: 20 | M7: 0.25
A8: 45712 | B8: 7 | C8: Caleb | D8: Joshua | E8: 3 | F8: 2 | G8: 1 | K8: Grand Total | L8: 26 | M8: 0.26923077
A9: 45712 | B9: 8 | C9: Caleb | D9: Joshua | E9: 3 | F9: 4 | G9: 0
A10: 45713 | B10: 9 | C10: Caleb | D10: Joshua | E10: 3 | F10: 5 | G10: 1
A11: 45713 | B11: 10 | C11: Caleb | D11: Joshua | E11: 3 | F11: 5 | G11: 0
A12: 45714 | B12: 11 | C12: Caleb | D12: Joshua | E12: 3 | F12: 12 | G12: 0
A13: 45715 | B13: 12 | C13: Caleb | D13: Joshua | E13: 3 | F13: 9 | G13: 0
A14: 45715 | B14: 13 | C14: Caleb | D14: Joshua | E14: 3 | F14: 10 | G14: 0
A15: 45716 | B15: 14 | C15: Joshua | D15: Joshua | E15: 3 | F15: 6 | G15: 0
A16: 45716 | B16: 15 | C16: Caleb | D16: Joshua | E16: 3 | F16: 4 | G16: 0
A17: 45720 | B17: 16 | C17: Joshua | D17: Joshua | E17: 3 | F17: 8 | G17: 0
A18: 45721 | B18: 17 | C18: Joshua | D18: Joshua | E18: 3 | F18: 4 | G18: 0
A19: 45722 | B19: 18 | C19: Caleb | D19: Joshua | E19: 3 | F19: 8 | G19: 0
A20: 45722 | B20: 19 | C20: Joshua | D20: Caleb | E20: 3 | F20: 6 | G20: 0
... A394: 46202 | B394: 289 | C394: Joshua | D394: Joshua | E394: OT2 | F394: 0 | G394: 1

Sheet Next Gen
A1: Game | B1: Player | C1: Throws | D1: Board Hits | E1: Land | F1: Points | G1: Height | H1: Board | I1: Date
A2: 71 | B2: Caleb | C2: 9 | D2: 8 | E2: 5 | F2: =SUMIF(Scores!$F$2:$F$926, 'Next Gen'!$A2, INDEX(Scores!$I$2:$Q$926, 0, MATCH($B2, Scores!$I$1:$Q$1, 0))) -> 13 | G2: =INDEX(Scores!$B$2:$B$926, MATCH('Next Gen'!$A3, Scores!$F$2:$F$926, 0)) -> high | H2: =INDEX(Scores!$D$2:$D$926, MATCH('Next Gen'!$A2, Scores!$F$2:$F$926, 0)) -> Original | I2: =INDEX(Scores!$E$2:$E$926, MATCH('Next Gen'!$A3, Scores!$F$2:$F$926, 0)) -> 45772 | W2: Accuracy - Board Hits per Throw
A3: 71 | B3: Joshua | C3: 9 | D3: 9 | E3: 4 | F3: =SUMIF(Scores!$F$2:$F$926, 'Next Gen'!$A3, INDEX(Scores!$I$2:$Q$926, 0, MATCH($B3, Scores!$I$1:$Q$1, 0))) -> 8 | G3: =INDEX(Scores!$B$2:$B$926, MATCH('Next Gen'!$A2, Scores!$F$2:$F$926, 0)) -> high | H3: =INDEX(Scores!$D$2:$D$926, MATCH('Next Gen'!$A3, Scores!$F$2:$F$926, 0)) -> Original | I3: =INDEX(Scores!$E$2:$E$926, MATCH('Next Gen'!$A2, Scores!$F$2:$F$926, 0)) -> 45772 | L3: Players | M3: Games | N3: Hits | O3: Landing | P3: Accuracy | Q3: Touch | R3: Efficiency | S3: Land Rate | T3: PPT | U3: PPG | W3: Touch - Landing per Board Hit
A4: 72 | B4: Caleb | C4: 9 | D4: 9 | E4: 2 | F4: =SUMIF(Scores!$F$2:$F$926, 'Next Gen'!$A4, INDEX(Scores!$I$2:$Q$926, 0, MATCH($B4, Scores!$I$1:$Q$1, 0))) -> 4 | G4: =INDEX(Scores!$B$2:$B$926, MATCH('Next Gen'!$A5, Scores!$F$2:$F$926, 0)) -> mid | H4: =INDEX(Scores!$D$2:$D$926, MATCH('Next Gen'!$A4, Scores!$F$2:$F$926, 0)) -> Original | I4: =INDEX(Scores!$E$2:$E$926, MATCH('Next Gen'!$A5, Scores!$F$2:$F$926, 0)) -> 45775 | L4: Caleb | M4: 59 | N4: 9.2542373 | O4: 5.7457627 | P4: 0.97849462 | Q4: 0.62087912 | R4: 2.1917404 | S4: 0.60752688 | T4: 1.3315412 | U4: 11.983871 | W4: Efficiency - Points per Landing
A5: 72 | B5: Joshua | C5: 9 | D5: 5 | E5: 1 | F5: =SUMIF(Scores!$F$2:$F$926, 'Next Gen'!$A5, INDEX(Scores!$I$2:$Q$926, 0, MATCH($B5, Scores!$I$1:$Q$1, 0))) -> 1 | G5: =INDEX(Scores!$B$2:$B$926, MATCH('Next Gen'!$A4, Scores!$F$2:$F$926, 0)) -> mid | H5: =INDEX(Scores!$D$2:$D$926, MATCH('Next Gen'!$A5, Scores!$F$2:$F$926, 0)) -> Original | I5: =INDEX(Scores!$E$2:$E$926, MATCH('Next Gen'!$A4, Scores!$F$2:$F$926, 0)) -> 45775 | L5: Daniel | M5: 1 | N5: 6 | O5: 4 | P5: 0.66666667 | Q5: 0.66666667 | R5: 1 | S5: 0.44444444 | T5: 0.44444444 | U5: 4
A6: 72 | B6: Daniel | C6: 9 | D6: 3 | E6: 0 | F6: =SUMIF(Scores!$F$2:$F$926, 'Next Gen'!$A6, INDEX(Scores!$I$2:$Q$926, 0, MATCH($B6, Scores!$I$1:$Q$1, 0))) -> 0 | G6: =INDEX(Scores!$B$2:$B$926, MATCH('Next Gen'!$A6, Scores!$F$2:$F$926, 0)) -> mid | H6: =INDEX(Scores!$D$2:$D$926, MATCH('Next Gen'!$A6, Scores!$F$2:$F$926, 0)) -> Original | I6: =INDEX(Scores!$E$2:$E$926, MATCH('Next Gen'!$A6, Scores!$F$2:$F$926, 0)) -> 45775 | L6: Joshua | M6: 59 | N6: 7.7966102 | O6: 5.6779661 | P6: 0.82437276 | Q6: 0.72826087 | R6: 1.8119403 | S6: 0.60035842 | T6: 1.0878136 | U6: 9.7903226
A7: 73 | B7: Joshua | C7: 9 | D7: 6 | E7: 4 | F7: =SUMIF(Scores!$F$2:$F$926, 'Next Gen'!$A7, INDEX(Scores!$I$2:$Q$926, 0, MATCH($B7, Scores!$I$1:$Q$1, 0))) -> 10 | G7: =INDEX(Scores!$B$2:$B$926, MATCH('Next Gen'!$A8, Scores!$F$2:$F$926, 0)) -> high | H7: =INDEX(Scores!$D$2:$D$926, MATCH('Next Gen'!$A7, Scores!$F$2:$F$926, 0)) -> Original | I7: =INDEX(Scores!$E$2:$E$926, MATCH('Next Gen'!$A8, Scores!$F$2:$F$926, 0)) -> 45775 | L7: Quadri | M7: 7 | N7: 6.1428571 | O7: 3.8571429 | P7: 0.68253968 | Q7: 0.62790698 | R7: 1.8148148 | S7: 0.42857143 | T7: 0.77777778 | U7: 7
A8: 73 | B8: Caleb | C8: 9 | D8: 9 | E8: 2 | F8: =SUMIF(Scores!$F$2:$F$926, 'Next Gen'!$A8, INDEX(Scores!$I$2:$Q$926, 0, MATCH($B8, Scores!$I$1:$Q$1, 0))) -> 2 | G8: =INDEX(Scores!$B$2:$B$926, MATCH('Next Gen'!$A7, Scores!$F$2:$F$926, 0)) -> high | H8: =INDEX(Scores!$D$2:$D$926, MATCH('Next Gen'!$A8, Scores!$F$2:$F$926, 0)) -> Original | I8: =INDEX(Scores!$E$2:$E$926, MATCH('Next Gen'!$A7, Scores!$F$2:$F$926, 0)) -> 45775 | L8: Veronica | M8: 3 | N8: 4 | O8: 2.6666667 | P8: 0.44444444 | Q8: 0.66666667 | R8: 1.875 | S8: 0.2962963 | T8: 0.55555556 | U8: 5
A9: 74 | B9: Caleb | C9: 9 | D9: 6 | E9: 4 | F9: =SUMIF(Scores!$F$2:$F$926, 'Next Gen'!$A9, INDEX(Scores!$I$2:$Q$926, 0, MATCH($B9, Scores!$I$1:$Q$1, 0))) -> 7 | G9: =INDEX(Scores!$B$2:$B$926, MATCH('Next Gen'!$A10, Scores!$F$2:$F$926, 0)) -> low | H9: =INDEX(Scores!$D$2:$D$926, MATCH('Next Gen'!$A9, Scores!$F$2:$F$926, 0)) -> Original | I9: =INDEX(Scores!$E$2:$E$926, MATCH('Next Gen'!$A10, Scores!$F$2:$F$926, 0)) -> 45775 | L9: Joseph | M9: 1 | N9: 6 | O9: 3 | P9: 0.66666667 | Q9: 0.5 | R9: 1 | S9: 0.33333333 | T9: 0.33333333 | U9: 3
A10: 74 | B10: Daniel | C10: 9 | D10: 4 | E10: 3 | F10: =SUMIF(Scores!$F$2:$F$926, 'Next Gen'!$A10, INDEX(Scores!$I$2:$Q$926, 0, MATCH($B10, Scores!$I$1:$Q$1, 0))) -> 3 | G10: =INDEX(Scores!$B$2:$B$926, MATCH('Next Gen'!$A11, Scores!$F$2:$F$926, 0)) -> low | H10: =INDEX(Scores!$D$2:$D$926, MATCH('Next Gen'!$A10, Scores!$F$2:$F$926, 0)) -> Original | I10: =INDEX(Scores!$E$2:$E$926, MATCH('Next Gen'!$A11, Scores!$F$2:$F$926, 0)) -> 45775 | L10: Theo | M10: 1 | N10: 2 | O10: 2 | P10: 0.22222222 | Q10: 1 | R10: 2.5 | S10: 0.22222222 | T10: 0.55555556 | U10: 5
A11: 74 | B11: Joshua | C11: 9 | D11: 5 | E11: 1 | F11: =SUMIF(Scores!$F$2:$F$926, 'Next Gen'!$A11, INDEX(Scores!$I$2:$Q$926, 0, MATCH($B11, Scores!$I$1:$Q$1, 0))) -> 1 | G11: =INDEX(Scores!$B$2:$B$926, MATCH('Next Gen'!$A9, Scores!$F$2:$F$926, 0)) -> low | H11: =INDEX(Scores!$D$2:$D$926, MATCH('Next Gen'!$A11, Scores!$F$2:$F$926, 0)) -> Original | I11: =INDEX(Scores!$E$2:$E$926, MATCH('Next Gen'!$A9, Scores!$F$2:$F$926, 0)) -> 45775 | L11: Total | M11: 131 | N11: 8.2061069 | O11: 5.480916 | P11: 0.87185726 | Q11: 0.66790698 | R11: 1.9860724 | S11: 0.58231955 | T11: 1.1565288 | U11: 10.408759
A12: 75 | B12: Joshua | C12: 12 | D12: 8 | E12: 6 | F12: =SUMIF(Scores!$F$2:$F$926, 'Next Gen'!$A12, INDEX(Scores!$I$2:$Q$926, 0, MATCH($B12, Scores!$I$1:$Q$1, 0))) -> 8 | G12: =INDEX(Scores!$B$2:$B$926, MATCH('Next Gen'!$A13, Scores!$F$2:$F$926, 0)) -> mid | H12: =INDEX(Scores!$D$2:$D$926, MATCH('Next Gen'!$A12, Scores!$F$2:$F$926, 0)) -> Original | I12: =INDEX(Scores!$E$2:$E$926, MATCH('Next Gen'!$A13, Scores!$F$2:$F$926, 0)) -> 45775
A13: 75 | B13: Caleb | C13: 12 | D13: 12 | E13: 5 | F13: =SUMIF(Scores!$F$2:$F$926, 'Next Gen'!$A13, INDEX(Scores!$I$2:$Q$926, 0, MATCH($B13, Scores!$I$1:$Q$1, 0))) -> 10 | G13: =INDEX(Scores!$B$2:$B$926, MATCH('Next Gen'!$A12, Scores!$F$2:$F$926, 0)) -> mid | H13: =INDEX(Scores!$D$2:$D$926, MATCH('Next Gen'!$A13, Scores!$F$2:$F$926, 0)) -> Original | I13: =INDEX(Scores!$E$2:$E$926, MATCH('Next Gen'!$A12, Scores!$F$2:$F$926, 0)) -> 45775
A14: 76 | B14: Caleb | C14: 9 | D14: 8 | E14: 3 | F14: =SUMIF(Scores!$F$2:$F$926, 'Next Gen'!$A14, INDEX(Scores!$I$2:$Q$926, 0, MATCH($B14, Scores!$I$1:$Q$1, 0))) -> 5 | G14: =INDEX(Scores!$B$2:$B$926, MATCH('Next Gen'!$A14, Scores!$F$2:$F$926, 0)) -> mid | H14: =INDEX(Scores!$D$2:$D$926, MATCH('Next Gen'!$A14, Scores!$F$2:$F$926, 0)) -> Original | I14: =INDEX(Scores!$E$2:$E$926, MATCH('Next Gen'!$A14, Scores!$F$2:$F$926, 0)) -> 45776
A15: 76 | B15: Joshua | C15: 9 | D15: 6 | E15: 0 | F15: =SUMIF(Scores!$F$2:$F$926, 'Next Gen'!$A15, INDEX(Scores!$I$2:$Q$926, 0, MATCH($B15, Scores!$I$1:$Q$1, 0))) -> 0 | G15: =INDEX(Scores!$B$2:$B$926, MATCH('Next Gen'!$A15, Scores!$F$2:$F$926, 0)) -> mid | H15: =INDEX(Scores!$D$2:$D$926, MATCH('Next Gen'!$A15, Scores!$F$2:$F$926, 0)) -> Original | I15: =INDEX(Scores!$E$2:$E$926, MATCH('Next Gen'!$A15, Scores!$F$2:$F$926, 0)) -> 45776
A16: 77 | B16: Joshua | C16: 9 | D16: 5 | E16: 3 | F16: =SUMIF(Scores!$F$2:$F$926, 'Next Gen'!$A16, INDEX(Scores!$I$2:$Q$926, 0, MATCH($B16, Scores!$I$1:$Q$1, 0))) -> 5 | G16: =INDEX(Scores!$B$2:$B$926, MATCH('Next Gen'!$A17, Scores!$F$2:$F$926, 0)) -> mid | H16: =INDEX(Scores!$D$2:$D$926, MATCH('Next Gen'!$A16, Scores!$F$2:$F$926, 0)) -> Original | I16: =INDEX(Scores!$E$2:$E$926, MATCH('Next Gen'!$A17, Scores!$F$2:$F$926, 0)) -> 45776
A17: 77 | B17: Quadri | C17: 9 | D17: 5 | E17: 3 | F17: =SUMIF(Scores!$F$2:$F$926, 'Next Gen'!$A17, INDEX(Scores!$I$2:$Q$926, 0, MATCH($B17, Scores!$I$1:$Q$1, 0))) -> 8 | G17: =INDEX(Scores!$B$2:$B$926, MATCH('Next Gen'!$A18, Scores!$F$2:$F$926, 0)) -> mid | H17: =INDEX(Scores!$D$2:$D$926, MATCH('Next Gen'!$A17, Scores!$F$2:$F$926, 0)) -> Original | I17: =INDEX(Scores!$E$2:$E$926, MATCH('Next Gen'!$A18, Scores!$F$2:$F$926, 0)) -> 45776
A18: 77 | B18: Caleb | C18: 9 | D18: 9 | E18: 1 | F18: =SUMIF(Scores!$F$2:$F$926, 'Next Gen'!$A18, INDEX(Scores!$I$2:$Q$926, 0, MATCH($B18, Scores!$I$1:$Q$1, 0))) -> 1 | G18: =INDEX(Scores!$B$2:$B$926, MATCH('Next Gen'!$A16, Scores!$F$2:$F$926, 0)) -> mid | H18: =INDEX(Scores!$D$2:$D$926, MATCH('Next Gen'!$A18, Scores!$F$2:$F$926, 0)) -> Original | I18: =INDEX(Scores!$E$2:$E$926, MATCH('Next Gen'!$A16, Scores!$F$2:$F$926, 0)) -> 45776
A19: 78 | B19: Caleb | C19: 9 | D19: 8 | E19: 5 | F19: =SUMIF(Scores!$F$2:$F$926, 'Next Gen'!$A19, INDEX(Scores!$I$2:$Q$926, 0, MATCH($B19, Scores!$I$1:$Q$1, 0))) -> 9 | G19: =INDEX(Scores!$B$2:$B$926, MATCH('Next Gen'!$A19, Scores!$F$2:$F$926, 0)) -> mid | H19: =INDEX(Scores!$D$2:$D$926, MATCH('Next Gen'!$A19, Scores!$F$2:$F$926, 0)) -> Original | I19: =INDEX(Scores!$E$2:$E$926, MATCH('Next Gen'!$A19, Scores!$F$2:$F$926, 0)) -> 45776
A20: 78 | B20: Daniel | C20: 9 | D20: 6 | E20: 2 | F20: =SUMIF(Scores!$F$2:$F$926, 'Next Gen'!$A20, INDEX(Scores!$I$2:$Q$926, 0, MATCH($B20, Scores!$I$1:$Q$1, 0))) -> 4 | G20: =INDEX(Scores!$B$2:$B$926, MATCH('Next Gen'!$A20, Scores!$F$2:$F$926, 0)) -> mid | H20: =INDEX(Scores!$D$2:$D$926, MATCH('Next Gen'!$A20, Scores!$F$2:$F$926, 0)) -> Original | I20: =INDEX(Scores!$E$2:$E$926, MATCH('Next Gen'!$A20, Scores!$F$2:$F$926, 0)) -> 45776
A21: 79 | B21: Daniel | C21: 9 | D21: 5 | E21: 3 | F21: =SUMIF(Scores!$F$2:$F$926, 'Next Gen'!$A21, INDEX(Scores!$I$2:$Q$926, 0, MATCH($B21, Scores!$I$1:$Q$1, 0))) -> 5 | G21: =INDEX(Scores!$B$2:$B$926, MATCH('Next Gen'!$A24, Scores!$F$2:$F$926, 0)) -> mid | H21: =INDEX(Scores!$D$2:$D$926, MATCH('Next Gen'!$A21, Scores!$F$2:$F$926, 0)) -> Original | I21: =INDEX(Scores!$E$2:$E$926, MATCH('Next Gen'!$A24, Scores!$F$2:$F$926, 0)) -> 45776
A22: 79 | B22: Caleb | C22: 9 | D22: 7 | E22: 3 | F22: =SUMIF(Scores!$F$2:$F$926, 'Next Gen'!$A22, INDEX(Scores!$I$2:$Q$926, 0, MATCH($B22, Scores!$I$1:$Q$1, 0))) -> 7 | G22: =INDEX(Scores!$B$2:$B$926, MATCH('Next Gen'!$A21, Scores!$F$2:$F$926, 0)) -> mid | H22: =INDEX(Scores!$D$2:$D$926, MATCH('Next Gen'!$A22, Scores!$F$2:$F$926, 0)) -> Original | I22: =INDEX(Scores!$E$2:$E$926, MATCH('Next Gen'!$A21, Scores!$F$2:$F$926, 0)) -> 45776
A23: 79 | B23: Joshua | C23: 9 | D23: 6 | E23: 1 | F23: =SUMIF(Scores!$F$2:$F$926, 'Next Gen'!$A23, INDEX(Scores!$I$2:$Q$926, 0, MATCH($B23, Scores!$I$1:$Q$1, 0))) -> 1 | G23: =INDEX(Scores!$B$2:$B$926, MATCH('Next Gen'!$A22, Scores!$F$2:$F$926, 0)) -> mid | H23: =INDEX(Scores!$D$2:$D$926, MATCH('Next Gen'!$A23, Scores!$F$2:$F$926, 0)) -> Original | I23: =INDEX(Scores!$E$2:$E$926, MATCH('Next Gen'!$A22, Scores!$F$2:$F$926, 0)) -> 45776
A24: 79 | B24: Quadri | C24: 9 | D24: 2 | E24: 1 | F24: =SUMIF(Scores!$F$2:$F$926, 'Next Gen'!$A24, INDEX(Scores!$I$2:$Q$926, 0, MATCH($B24, Scores!$I$1:$Q$1, 0))) -> 1 | G24: =INDEX(Scores!$B$2:$B$926, MATCH('Next Gen'!$A23, Scores!$F$2:$F$926, 0)) -> mid | H24: =INDEX(Scores!$D$2:$D$926, MATCH('Next Gen'!$A24, Scores!$F$2:$F$926, 0)) -> Original | I24: =INDEX(Scores!$E$2:$E$926, MATCH('Next Gen'!$A23, Scores!$F$2:$F$926, 0)) -> 45776
A25: 80 | B25: Caleb | C25: 9 | D25: 8 | E25: 6 | F25: =SUMIF(Scores!$F$2:$F$926, 'Next Gen'!$A25, INDEX(Scores!$I$2:$Q$926, 0, MATCH($B25, Scores!$I$1:$Q$1, 0))) -> 12 | G25: =INDEX(Scores!$B$2:$B$926, MATCH('Next Gen'!$A27, Scores!$F$2:$F$926, 0)) -> mid | H25: =INDEX(Scores!$D$2:$D$926, MATCH('Next Gen'!$A25, Scores!$F$2:$F$926, 0)) -> Original | I25: =INDEX(Scores!$E$2:$E$926, MATCH('Next Gen'!$A27, Scores!$F$2:$F$926, 0)) -> 45777
A26: 80 | B26: Quadri | C26: 9 | D26: 4 | E26: 3 | F26: =SUMIF(Scores!$F$2:$F$926, 'Next Gen'!$A26, INDEX(Scores!$I$2:$Q$926, 0, MATCH($B26, Scores!$I$1:$Q$1, 0))) -> 4 | G26: =INDEX(Scores!$B$2:$B$926, MATCH('Next Gen'!$A26, Scores!$F$2:$F$926, 0)) -> mid | H26: =INDEX(Scores!$D$2:$D$926, MATCH('Next Gen'!$A26, Scores!$F$2:$F$926, 0)) -> Original | I26: =INDEX(Scores!$E$2:$E$926, MATCH('Next Gen'!$A26, Scores!$F$2:$F$926, 0)) -> 45777
A27: 80 | B27: Joshua | C27: 9 | D27: 6 | E27: 2 | F27: =SUMIF(Scores!$F$2:$F$926, 'Next Gen'!$A27, INDEX(Scores!$I$2:$Q$926, 0, MATCH($B27, Scores!$I$1:$Q$1, 0))) -> 3 | G27: =INDEX(Scores!$B$2:$B$926, MATCH('Next Gen'!$A25, Scores!$F$2:$F$926, 0)) -> mid | H27: =INDEX(Scores!$D$2:$D$926, MATCH('Next Gen'!$A27, Scores!$F$2:$F$926, 0)) -> Original | I27: =INDEX(Scores!$E$2:$E$926, MATCH('Next Gen'!$A25, Scores!$F$2:$F$926, 0)) -> 45777
A28: 81 | B28: Caleb | C28: 9 | D28: 8 | E28: 4 | F28: =SUMIF(Scores!$F$2:$F$926, 'Next Gen'!$A28, INDEX(Scores!$I$2:$Q$926, 0, MATCH($B28, Scores!$I$1:$Q$1, 0))) -> 6 | G28: =INDEX(Scores!$B$2:$B$926, MATCH('Next Gen'!$A28, Scores!$F$2:$F$926, 0)) -> high | H28: =INDEX(Scores!$D$2:$D$926, MATCH('Next Gen'!$A28, Scores!$F$2:$F$926, 0)) -> Original | I28: =INDEX(Scores!$E$2:$E$926, MATCH('Next Gen'!$A28, Scores!$F$2:$F$926, 0)) -> 45777
A29: 81 | B29: Joshua | C29: 9 | D29: 4 | E29: 0 | F29: =SUMIF(Scores!$F$2:$F$926, 'Next Gen'!$A29, INDEX(Scores!$I$2:$Q$926, 0, MATCH($B29, Scores!$I$1:$Q$1, 0))) -> 0 | G29: =INDEX(Scores!$B$2:$B$926, MATCH('Next Gen'!$A29, Scores!$F$2:$F$926, 0)) -> high | H29: =INDEX(Scores!$D$2:$D$926, MATCH('Next Gen'!$A29, Scores!$F$2:$F$926, 0)) -> Original | I29: =INDEX(Scores!$E$2:$E$926, MATCH('Next Gen'!$A29, Scores!$F$2:$F$926, 0)) -> 45777
A30: 82 | B30: Caleb | C30: 9 | D30: 8 | E30: 6 | F30: =SUMIF(Scores!$F$2:$F$926, 'Next Gen'!$A30, INDEX(Scores!$I$2:$Q$926, 0, MATCH($B30, Scores!$I$1:$Q$1, 0))) -> 12 | G30: =INDEX(Scores!$B$2:$B$926, MATCH('Next Gen'!$A30, Scores!$F$2:$F$926, 0)) -> low | H30: =INDEX(Scores!$D$2:$D$926, MATCH('Next Gen'!$A30, Scores!$F$2:$F$926, 0)) -> Original | I30: =INDEX(Scores!$E$2:$E$926, MATCH('Next Gen'!$A30, Scores!$F$2:$F$926, 0)) -> 45777
A31: 82 | B31: Daniel | C31: 9 | D31: 3 | E31: 2 | F31: =SUMIF(Scores!$F$2:$F$926, 'Next Gen'!$A31, INDEX(Scores!$I$2:$Q$926, 0, MATCH($B31, Scores!$I$1:$Q$1, 0))) -> 2 | G31: =INDEX(Scores!$B$2:$B$926, MATCH('Next Gen'!$A31, Scores!$F$2:$F$926, 0)) -> low | H31: =INDEX(Scores!$D$2:$D$926, MATCH('Next Gen'!$A31, Scores!$F$2:$F$926, 0)) -> Original | I31: =INDEX(Scores!$E$2:$E$926, MATCH('Next Gen'!$A31, Scores!$F$2:$F$926, 0)) -> 45777
A32: 82 | B32: Joshua | C32: 9 | D32: 7 | E32: 2 | F32: =SUMIF(Scores!$F$2:$F$926, 'Next Gen'!$A32, INDEX(Scores!$I$2:$Q$926, 0, MATCH($B32, Scores!$I$1:$Q$1, 0))) -> 5 | G32: =INDEX(Scores!$B$2:$B$926, MATCH('Next Gen'!$A32, Scores!$F$2:$F$926, 0)) -> low | H32: =INDEX(Scores!$D$2:$D$926, MATCH('Next Gen'!$A32, Scores!$F$2:$F$926, 0)) -> Original | I32: =INDEX(Scores!$E$2:$E$926, MATCH('Next Gen'!$A32, Scores!$F$2:$F$926, 0)) -> 45777
A33: 83 | B33: Caleb | C33: 9 | D33: 9 | E33: 6 | F33: =SUMIF(Scores!$F$2:$F$926, 'Next Gen'!$A33, INDEX(Scores!$I$2:$Q$926, 0, MATCH($B33, Scores!$I$1:$Q$1, 0))) -> 12 | G33: =INDEX(Scores!$B$2:$B$926, MATCH('Next Gen'!$A33, Scores!$F$2:$F$926, 0)) -> mid | H33: =INDEX(Scores!$D$2:$D$926, MATCH('Next Gen'!$A33, Scores!$F$2:$F$926, 0)) -> Original | I33: =INDEX(Scores!$E$2:$E$926, MATCH('Next Gen'!$A33, Scores!$F$2:$F$926, 0)) -> 45777
A34: 83 | B34: Joshua | C34: 9 | D34: 5 | E34: 3 | F34: =SUMIF(Scores!$F$2:$F$926, 'Next Gen'!$A34, INDEX(Scores!$I$2:$Q$926, 0, MATCH($B34, Scores!$I$1:$Q$1, 0))) -> 5 | G34: =INDEX(Scores!$B$2:$B$926, MATCH('Next Gen'!$A34, Scores!$F$2:$F$926, 0)) -> mid | H34: =INDEX(Scores!$D$2:$D$926, MATCH('Next Gen'!$A34, Scores!$F$2:$F$926, 0)) -> Original | I34: =INDEX(Scores!$E$2:$E$926, MATCH('Next Gen'!$A34, Scores!$F$2:$F$926, 0)) -> 45777
A35: 84 | B35: Caleb | C35: 9 | D35: 9 | E35: 5 | F35: =SUMIF(Scores!$F$2:$F$926, 'Next Gen'!$A35, INDEX(Scores!$I$2:$Q$926, 0, MATCH($B35, Scores!$I$1:$Q$1, 0))) -> 10 | G35: =INDEX(Scores!$B$2:$B$926, MATCH('Next Gen'!$A35, Scores!$F$2:$F$926, 0)) -> mid | H35: =INDEX(Scores!$D$2:$D$926, MATCH('Next Gen'!$A35, Scores!$F$2:$F$926, 0)) -> Original | I35: =INDEX(Scores!$E$2:$E$926, MATCH('Next Gen'!$A35, Scores!$F$2:$F$926, 0)) -> 45778
A36: 84 | B36: Joshua | C36: 9 | D36: 4 | E36: 3 | F36: =SUMIF(Scores!$F$2:$F$926, 'Next Gen'!$A36, INDEX(Scores!$I$2:$Q$926, 0, MATCH($B36, Scores!$I$1:$Q$1, 0))) -> 5 | G36: =INDEX(Scores!$B$2:$B$926, MATCH('Next Gen'!$A36, Scores!$F$2:$F$926, 0)) -> mid | H36: =INDEX(Scores!$D$2:$D$926, MATCH('Next Gen'!$A36, Scores!$F$2:$F$926, 0)) -> Original | I36: =INDEX(Scores!$E$2:$E$926, MATCH('Next Gen'!$A36, Scores!$F$2:$F$926, 0)) -> 45778
A37: 85 | B37: Caleb | C37: 12 | D37: 10 | E37: 6 | F37: =SUMIF(Scores!$F$2:$F$926, 'Next Gen'!$A37, INDEX(Scores!$I$2:$Q$926, 0, MATCH($B37, Scores!$I$1:$Q$1, 0))) -> 10 | G37: =INDEX(Scores!$B$2:$B$926, MATCH('Next Gen'!$A37, Scores!$F$2:$F$926, 0)) -> high | H37: =INDEX(Scores!$D$2:$D$926, MATCH('Next Gen'!$A37, Scores!$F$2:$F$926, 0)) -> Original | I37: =INDEX(Scores!$E$2:$E$926, MATCH('Next Gen'!$A37, Scores!$F$2:$F$926, 0)) -> 45778
A38: 85 | B38: Joshua | C38: 12 | D38: 9 | E38: 3 | F38: =SUMIF(Scores!$F$2:$F$926, 'Next Gen'!$A38, INDEX(Scores!$I$2:$Q$926, 0, MATCH($B38, Scores!$I$1:$Q$1, 0))) -> 6 | G38: =INDEX(Scores!$B$2:$B$926, MATCH('Next Gen'!$A38, Scores!$F$2:$F$926, 0)) -> high | H38: =INDEX(Scores!$D$2:$D$926, MATCH('Next Gen'!$A38, Scores!$F$2:$F$926, 0)) -> Original | I38: =INDEX(Scores!$E$2:$E$926, MATCH('Next Gen'!$A38, Scores!$F$2:$F$926, 0)) -> 45778
A39: 86 | B39: Caleb | C39: 9 | D39: 6 | E39: 4 | F39: =SUMIF(Scores!$F$2:$F$926, 'Next Gen'!$A39, INDEX(Scores!$I$2:$Q$926, 0, MATCH($B39, Scores!$I$1:$Q$1, 0))) -> 8 | G39: =INDEX(Scores!$B$2:$B$926, MATCH('Next Gen'!$A39, Scores!$F$2:$F$926, 0)) -> low | H39: =INDEX(Scores!$D$2:$D$926, MATCH('Next Gen'!$A39, Scores!$F$2:$F$926, 0)) -> Original | I39: =INDEX(Scores!$E$2:$E$926, MATCH('Next Gen'!$A39, Scores!$F$2:$F$926, 0)) -> 45778
... A42: 87 | B42: Joshua | C42: 9 | D42: 6 | E42: 1 | F42: =SUMIF(Scores!$F$2:$F$926, 'Next Gen'!$A42, INDEX(Scores!$I$2:$Q$926, 0, MATCH($B42, Scores!$I$1:$Q$1, 0))) -> 3 | G42: =INDEX(Scores!$B$2:$B$926, MATCH('Next Gen'!$A42, Scores!$F$2:$F$926, 0)) -> low | H42: =INDEX(Scores!$D$2:$D$926, MATCH('Next Gen'!$A42, Scores!$F$2:$F$926, 0)) -> Original | I42: =INDEX(Scores!$E$2:$E$926, MATCH('Next Gen'!$A42, Scores!$F$2:$F$926, 0)) -> 45778
...

Sheet Achievements
A1: Trifecta (three 3s in a single round) | D1: Perfect Touch (land every board hit)
